<?xml version="1.0" ?>
<!-- =================================================================================== -->
<!-- |    This document was autogenerated by xacro from inverted_pendulum.urdf.xacro   | -->
<!-- |    EDITING THIS FILE BY HAND IS NOT RECOMMENDED                                 | -->
<!-- =================================================================================== -->
<!-->The overall basic frame is robot tag.<-->
<robot name="motor_xacro" xmlns:controller="http://playerstage.sourceforge.net/gazebo/xmlschema/#controller" xmlns:interface="http://playerstage.sourceforge.net/gazebo/xmlschema/#interface" xmlns:sensor="http://playerstage.sourceforge.net/gazebo/xmlschema/#sensor" xmlns:xacro="http://www.ros.org/wiki/xacro">
  <!-->First part is the description of robot.<-->
  <link name="motor">
    <visual>
      <geometry>
        <box size="0.15 0.06 0.06"/>
      </geometry>
      <origin rpy="0 0 0" xyz="0 0 0"/>
      <material name="white">
        <color rgba="1 1 1 1"/>
      </material>
    </visual>
    <collision>
      <geometry>
        <box size="0.15 0.06 0.06"/>
      </geometry>
    </collision>
    <inertial>
      <mass value="0.8"/>
      <inertia ixx="1.0" ixy="0.0" ixz="0.0" iyy="1.0" iyz="0.0" izz="1.0"/>
    </inertial>
  </link>
  <link name="pendulum">
    <visual>
      <geometry>
        <cylinder length="0.4" radius="0.02"/>
      </geometry>
      <origin rpy="0 0 0" xyz="0.16 0 0"/>
      <material name="orange">
        <color rgba="0.5 0.5 0 0"/>
      </material>
    </visual>
    <collision>
      <geometry>
        <cylinder length="0.4" radius="0.02"/>
      </geometry>
    </collision>
    <inertial>
      <mass value="1.3565"/>
      <inertia ixx="1.0" ixy="0.0" ixz="0.0" iyy="1.0" iyz="0.0" izz="1.0"/>
    </inertial>
  </link>
  <joint name="motor_to_pendulum" type="continuous">
    <parent link="motor"/>
    <child link="pendulum"/>
    <axis xyz="1 0 0"/>
    <origin rpy="-1.5707 0 0" xyz="0.16 0 0.03"/>
  </joint>
  <!-->Second part is the controller applied on the model.<-->
  <gazebo>
    <plugin>
	</plugin>
  </gazebo>
</robot>

